Workbook

Sheet Summary
A1: CrowBox - parts list and cost
A2: Model v2_3 + new files (Wiring_v2, FieldModules, JunctionBox_v2, Panels_v3). Prices are estimates in USD, Oct 2026.
A4: How to use
A5: Type Y in the yellow 'Have?' cells (Buy and Tooling tabs) for anything you already own, e.g. Y next to the MG996R servos. 'Still to buy' updates. Blue numbers are inputs you can change; black are formulas; green pull from another tab.
A7: Assumptions
A8: Fastener spare | C8: 0.1 | D8: added before rounding up to packs
A9: Cable spare | C9: 0.1 | D9: on top of route + inside-box + end slack
A10: Print waste | C10: 0.15 | D10: failed prints, supports, purge
A12: Cost by phase
A13: Phase | B13: What | C13: Total $ | D13: Still to buy $
A14: Build | B14: Everything to build and run the box now | C14: =SUMIF(Buy!$M$2:$M$109,"Build",Buy!$J$2:$J$109) -> 1306.8 | D14: =SUMIF(Buy!$M$2:$M$109,"Build",Buy!$L$2:$L$109) -> 1306.8
A15: Phase 5 | B15: Cellular (Notecard) | C15: =SUMIF(Buy!$M$2:$M$109,"Phase 5",Buy!$J$2:$J$109) -> 74 | D15: =SUMIF(Buy!$M$2:$M$109,"Phase 5",Buy!$L$2:$L$109) -> 74
A16: Phase 7 | B16: Coral accelerator (dropped 2026-10-17) | C16: =SUMIF(Buy!$M$2:$M$109,"Phase 7",Buy!$J$2:$J$109) -> 68 | D16: =SUMIF(Buy!$M$2:$M$109,"Phase 7",Buy!$L$2:$L$109) -> 68
A17: Phase 9 | B17: Solar: panel, tilt kit, controller, cable | C17: =SUMIF(Buy!$M$2:$M$109,"Phase 9",Buy!$J$2:$J$109) -> 138.97 | D17: =SUMIF(Buy!$M$2:$M$109,"Phase 9",Buy!$L$2:$L$109) -> 138.97
A18: Paused | B18: IR beam pairs | C18: =SUMIF(Buy!$M$2:$M$109,"Paused",Buy!$J$2:$J$109) -> 18 | D18: =SUMIF(Buy!$M$2:$M$109,"Paused",Buy!$L$2:$L$109) -> 18
A19: All parts | B19: Build + later phases + paused | C19: =SUM(C14:C18) -> 1605.77 | D19: =SUM(D14:D18) -> 1605.77
A20: Tooling (separate) | B20: see Tooling tab | C20: =Tooling!C23 -> 184 | D20: =Tooling!E23 -> 184
A21: Options (not in totals) | B21: clear polycarbonate front panel | C21: =SUMIF(Buy!$M$2:$M$109,"Option",Buy!$J$2:$J$109) -> 160
A22: Option: McMaster brackets | B22: 78 x 5537T935 at ~$5.50 instead of the generic kits | C22: =78*5.5-Buy!J3 -> 385 | F22: extra cost over the generic kits
A24: Build cost by section
A25: Section | C25: Total $ | D25: Still to buy $
A26: Frame | C26: =SUMIFS(Buy!$J$2:$J$109,Buy!$B$2:$B$109,"Frame",Buy!$M$2:$M$109,"Build") -> 195.8 | D26: =SUMIFS(Buy!$L$2:$L$109,Buy!$B$2:$B$109,"Frame",Buy!$M$2:$M$109,"Build") -> 195.8
A27: Fasteners | C27: =SUMIFS(Buy!$J$2:$J$109,Buy!$B$2:$B$109,"Fasteners",Buy!$M$2:$M$109,"Build") -> 176 | D27: =SUMIFS(Buy!$L$2:$L$109,Buy!$B$2:$B$109,"Fasteners",Buy!$M$2:$M$109,"Build") -> 176
A28: Wood & sheet | C28: =SUMIFS(Buy!$J$2:$J$109,Buy!$B$2:$B$109,"Wood & sheet",Buy!$M$2:$M$109,"Build") -> 124 | D28: =SUMIFS(Buy!$L$2:$L$109,Buy!$B$2:$B$109,"Wood & sheet",Buy!$M$2:$M$109,"Build") -> 124
A29: Cut service | C29: =SUMIFS(Buy!$J$2:$J$109,Buy!$B$2:$B$109,"Cut service",Buy!$M$2:$M$109,"Build") -> 94 | D29: =SUMIFS(Buy!$L$2:$L$109,Buy!$B$2:$B$109,"Cut service",Buy!$M$2:$M$109,"Build") -> 94
A30: Junction box | C30: =SUMIFS(Buy!$J$2:$J$109,Buy!$B$2:$B$109,"Junction box",Buy!$M$2:$M$109,"Build") -> 140 | D30: =SUMIFS(Buy!$L$2:$L$109,Buy!$B$2:$B$109,"Junction box",Buy!$M$2:$M$109,"Build") -> 140
A31: Vision box | C31: =SUMIFS(Buy!$J$2:$J$109,Buy!$B$2:$B$109,"Vision box",Buy!$M$2:$M$109,"Build") -> 82 | D31: =SUMIFS(Buy!$L$2:$L$109,Buy!$B$2:$B$109,"Vision box",Buy!$M$2:$M$109,"Build") -> 82
A32: Field modules | C32: =SUMIFS(Buy!$J$2:$J$109,Buy!$B$2:$B$109,"Field modules",Buy!$M$2:$M$109,"Build") -> 160 | D32: =SUMIFS(Buy!$L$2:$L$109,Buy!$B$2:$B$109,"Field modules",Buy!$M$2:$M$109,"Build") -> 160
A33: Power | C33: =SUMIFS(Buy!$J$2:$J$109,Buy!$B$2:$B$109,"Power",Buy!$M$2:$M$109,"Build") -> 68 | D33: =SUMIFS(Buy!$L$2:$L$109,Buy!$B$2:$B$109,"Power",Buy!$M$2:$M$109,"Build") -> 68
A34: Wiring | C34: =SUMIFS(Buy!$J$2:$J$109,Buy!$B$2:$B$109,"Wiring",Buy!$M$2:$M$109,"Build") -> 205 | D34: =SUMIFS(Buy!$L$2:$L$109,Buy!$B$2:$B$109,"Wiring",Buy!$M$2:$M$109,"Build") -> 205
A35: Filament | C35: =SUMIFS(Buy!$J$2:$J$109,Buy!$B$2:$B$109,"Filament",Buy!$M$2:$M$109,"Build") -> 44 | D35: =SUMIFS(Buy!$L$2:$L$109,Buy!$B$2:$B$109,"Filament",Buy!$M$2:$M$109,"Build") -> 44
A36: Install | C36: =SUMIFS(Buy!$J$2:$J$109,Buy!$B$2:$B$109,"Install",Buy!$M$2:$M$109,"Build") -> 18 | D36: =SUMIFS(Buy!$L$2:$L$109,Buy!$B$2:$B$109,"Install",Buy!$M$2:$M$109,"Build") -> 18
A37: Build total (check) | C37: =SUM(C26:C36) -> 1306.8 | D37: =SUM(D26:D36) -> 1306.8
A39: Key quantities
A40: 2020 extrusion | C40: =Cut!E32 -> 35 | D40: bars, from 15 x 1000 mm sticks
A41: Corner brackets | C41: =Buy!E3 -> 78 | D41: 70 in model + 8 roof
A42: M5 T-nuts (plus kit ones) | C42: =Buy!E4 -> 150 | D42: plus 2 per bracket in the kits
A43: M5 screws + bolts | C43: =SUMIF(Fasteners!$A$2:$A$41,"M5x*",Fasteners!$C$2:$C$41) -> 152 | D43: 8 / 10 / 12 / 16 / 20 / 25 / 50 / 75 mm - see Fasteners
A44: Cable runs | C44: =COUNTA(Wiring!A2:A20) -> 19 | D44: see Wiring; 13 end at the JB (1 reserved)
A45: Printed parts | C45: =SUM(Print!C2:C14) -> 17 | D45: see Print
...

Sheet Fasteners
A1: Key (size) | B1: Used on | C1: Qty | D1: Goes into | E1: Why this length (clamped stack -> screw)
A2: M5x8 BHCS | B2: Pit light ring -> pit top bars | C2: 4 | D2: M5 T-nut | E2: ring lip 2.5 + washer 1 = 3.5 -> 8. M5x10 would hit the extrusion core.
A3: M5x8 BHCS | B3: Vision box ears -> reward crossbars (drill ears 4.5 -> 5.5 mm) | C3: 4 | D3: M5 T-nut | E3: ear 4 -> 8
A4: M5x10 BHCS | B4: Bottom plate -> vision crossbar (back row) | C4: 6 | D4: M5 T-nut | E4: plate 4.75 (0.187in) -> 10
A5: M5x10 BHCS | B5: Bottom plate -> front bar (X -100, -170, +170) | C5: 3 | D5: M5 T-nut | E5: plate 4.75 -> 10. No shims needed with the 0.187in plate.
A6: M5x10 BHCS | B6: Chute bracket 35 deg -> bars | C6: 4 | D6: M5 T-nut | E6: 5 mm base -> 10. Not M5x12: it bottoms out in the slot.
A7: M5x10 BHCS | B7: Chute -> chute bracket | C7: 4 | D7: M5 hex nut in the bracket's side slots
A8: M5x12 BHCS | B8: Side panels -> posts + side bars (16 per side) | C8: 32 | D8: M5 T-nut | E8: 6 mm ply + washer 1 -> 12
A9: M5x12 BHCS | B9: Back panel -> posts + bars | C9: 20 | D9: M5 T-nut | E9: 6 mm ply + washer 1 -> 12
A10: M5x12 BHCS | B10: Roof plywood -> top bars | C10: 11 | D10: M5 T-nut | E10: 6 mm ply + washer 1 -> 12
A11: M5x12 BHCS | B11: Bay floor -> bars | C11: 13 | D11: M5 T-nut | E11: 6 mm ply + washer 1 -> 12
A12: M5x12 BHCS | B12: Battery shelf -> bottom side bars (new holes) | C12: 4 | D12: M5 T-nut | E12: 6 mm ply + washer 1 -> 12
A13: M5x12 BHCS | B13: PIR housing -> bottom plate -> front bar (no washer) | C13: 2 | D13: M5 T-nut | E13: housing floor 3 + plate 4.75 -> 12
A14: M5x16 BHCS | B14: Front panel through 5 mm standoffs (18 holes minus 4 perch) | C14: 14 | D14: M5 T-nut | E14: 6 ply + 5 spacer + washer 1 -> 16
A15: M5x16 BHCS | B15: Solar tilt-kit feet -> roof -> top bars | C15: 4 | D15: M5 T-nut | E15: 3 foot + 6 ply + washer 1 -> 16
A16: M5x16 BHCS | B16: Signal pod -> plate -> front bar (replaces the M5x10 at X +100) | C16: 1 | D16: M5 T-nut | E16: pod floor 6 + plate 4.75 -> 16
A17: M5x16 BHCS | B17: Junction box top flange -> back panel -> bay back bar | C17: 2 | D17: M5 T-nut | E17: flange 5 + ply 6 + washer 1 -> 16
A18: M5x16 BHCS | B18: Gate actuator rear mounts -> front posts (?) | C18: 2 | D18: M5 T-nut (5278N43 in model) | E18: verify against your actuator mount
A19: M5x20 BHCS | B19: Junction box bottom flange -> back panel (no bar behind) | C19: 2 | D19: M5 nyloc + washers inside | E19: flange 5 + ply 6 + 2 washers + nyloc -> 20
... A26: M5 fender washer | B26: Legs (12) + skirt bolts (2 each) | C26: 20 | D26: - | E26: 5.3 x 20 mm, spreads load on the 2x2
A27: M5 nyloc | B27: JB bottom bolts 2 + skirt bolts 4 | C27: 6 | D27: -
A28: M5 hex nut | B28: Chute -> chute bracket | C28: 4 | D28: - | E28: fits the bracket's side-entry slots
A29: M5 spacer 5mm | B29: Front panel standoffs | C29: 18 | D29: - | E29: unthreaded, 5 mm long, ~10 mm OD
A30: M4x16 BHCS | B30: Reward load cell fixed end (through plate + 5 mm spacer) | C30: 2 | D30: load cell M4 thread | E30: plate 4.75 + spacer 5 -> 16 (6 mm thread engagement)
A31: M4x16 BHCS | B31: Solar charge controller -> battery shelf | C31: 2 | D31: M4 nyloc | E31: controller tab + 6 ply + washers + nut
A32: M4x20 BHCS | B32: Reward tray -> load cell (through 11 mm spacers) | C32: 2 | D32: load cell M4 thread | E32: tray 2 + spacer 11 -> 20 (7 mm engagement)
A33: M4x20 BHCS | B33: Hopper cradles -> bay floor (2 per cradle) | C33: 6 | D33: M4 nyloc | E33: foot 5 + ply 6 + 2 washers + nyloc -> 20
A34: M4 nyloc | B34: Cradles 6 + controller 2 | C34: 8 | D34: -
A35: M4 washer | B35: Load cell 4 + cradles 12 + controller 4 | C35: 20 | D35: -
A36: Spacer M4x11 | B36: Tray -> load cell (McMaster 92871A311) | C36: 2 | D36: - | E36: as modeled
A37: Spacer M4x5 | B37: Load cell fixed end (McMaster 92871A008) | C37: 2 | D37: - | E37: as modeled
A38: #8x2-1/2 wood | B38: Ground aprons + raised front apron -> legs (2 per joint) | C38: 16 | D38: 2x2 | E38: exterior coated; pre-drill
A39: #8x1-1/4 wood | B39: 1x2 diagonals -> legs/aprons (2 per end) | C39: 12 | D39: 2x2 | E39: exterior coated; pre-drill
A40: #6x5/8 wood | B40: Skirt corner cleats (2 per panel per cleat) | C40: 16 | D40: 3/4in cleat
A41: #6x3/4 wood | B41: Perch rod lock screws | C41: 4 | D41: 1-1/4in dowel | E41: through the printed arm into the rod
A43: Brackets: each of the 78 corner brackets also uses 2 x M5x10 (or M5x8 for <=3.5 mm brackets) + 2 T-nuts, included in the bracket kits on the Buy tab.
A44: Length rule for 2020 drop-in T-nuts: screw length = clamped thickness + 4 to 6 mm. Longer screws hit the extrusion core before they clamp.

Sheet Wiring
A1: ID | B1: Run | C1: From | D1: To | E1: Buy as | F1: Type key | G1: Cond. | H1: AWG | I1: OD mm | J1: Gland / hole | K1: Route in model (mm) | L1: Inside box (mm) | M1: End slack (mm) | N1: Buy length (m) | O1: Conductor map | P1: Notes
A2: W01 | B2: Doser servo 1 | C2: MG996R on cradle 1 | D2: JB G1 (upper-right hole) | E2: 3-core 22 AWG round | F2: 3C22 | G2: 3 | H2: 22 | I2: 4.2 | J2: G1-UR | K2: 740 | L2: 250 | M2: 150 | N2: =ROUNDUP((K2+L2+M2)*(1+Summary!$C$9)/100,0)/10 -> 1.3 | O2: Black/brown GND -> GND bus; red +6 V servo rail; white/orange PWM -> ESP32 GPIO | P2: Servo plug mates with a 3-pin 2.54 mm male header soldered to the cable end; heat-shrink + zip tie. Down through the left bay-floor hole.
A3: W02 | B3: Doser servo 2 | C3: MG996R on cradle 2 | D3: JB G1 (lower-right) | E3: 3-core 22 AWG round | F3: 3C22 | G3: 3 | H3: 22 | I3: 4.2 | J3: G1-LR | K3: 598 | L3: 250 | M3: 150 | N3: =ROUNDUP((K3+L3+M3)*(1+Summary!$C$9)/100,0)/10 -> 1.1 | O3: as W01 | P3: Left bay-floor hole.
A4: W03 | B4: Doser servo 3 | C4: MG996R on cradle 3 | D4: JB G3 (upper-left) | E4: 3-core 22 AWG round | F4: 3C22 | G4: 3 | H4: 22 | I4: 4.2 | J4: G3-UL | K4: 602 | L4: 250 | M4: 150 | N4: =ROUNDUP((K4+L4+M4)*(1+Summary!$C$9)/100,0)/10 -> 1.2 | O4: as W01 | P4: Right bay-floor hole.
A5: W04 | B5: IR beam pairs x3 (PAUSED) | C5: Bay floor, behind cradle 2 | D5: JB G1 (upper-left) | E5: 6-core 24 AWG round | F5: 6C24 | G5: 6 | H5: 24 | I5: 4.8 | J5: G1-UL | K5: 460 | L5: 250 | M5: 600 | N5: =ROUNDUP((K5+L5+M5)*(1+Summary!$C$9)/100,0)/10 -> 1.5 | O5: +5 V, GND, OUT1, OUT2, OUT3 -> MCP23017 inputs, 1 spare | P5: Paused: buy later. One shared cable instead of 3. 600 mm end slack = branches to the 3 hoppers. Plug the gland hole until then.
A6: W05 | B6: Gate actuator L | C6: Actuator L (bottom end) | D6: JB G1 (lower-left) | E6: 2-core 20 AWG round | F6: 2C20 | G6: 2 | H6: 20 | I6: 4.3 | J6: G1-LL | K6: 743 | L6: 250 | M6: 150 | N6: =ROUNDUP((K6+L6+M6)*(1+Summary!$C$9)/100,0)/10 -> 1.3 | O6: Red/black -> L298N OUT1/OUT2 | P6: Butt-splice to the actuator leads with adhesive heat-shrink.
A7: W06 | B7: Gate actuator R | C7: Actuator R (bottom end) | D7: JB G3 (lower-right) | E7: 2-core 20 AWG round | F7: 2C20 | G7: 2 | H7: 20 | I7: 4.3 | J7: G3-LR | K7: 733 | L7: 250 | M7: 150 | N7: =ROUNDUP((K7+L7+M7)*(1+Summary!$C$9)/100,0)/10 -> 1.3 | O7: Red/black -> L298N OUT3/OUT4 | P7: as W05
A8: W07 | B8: Signal pod (3 LEDs + buzzer) | C8: Signal pod behind PIR slot | D8: JB G3 (lower-left) | E8: 6-core 24 AWG round | F8: 6C24 | G8: 6 | H8: 24 | I8: 4.8 | J8: G3-LL | K8: 602 | L8: 250 | M8: 150 | N8: =ROUNDUP((K8+L8+M8)*(1+Summary!$C$9)/100,0)/10 -> 1.2 | O8: LED green, LED red, LED blue (330 ohm each, resistors in the JB) -> MCP23017; BUZ -> ESP32 PWM pin; +5 V; GND | P8: Drops down the gap behind the front panel, runs back under the front bar at Z 248.
A9: W08 | B9: Vision box link | C9: Vision box (PG9, back wall) | D9: JB G4 | E9: Cat6 stranded patch cable (8 x 24 AWG) | F9: CAT6 | G9: 8 | H9: 24 | I9: 6 | J9: G4 | K9: 287 | L9: 350 | M9: 100 | N9: =ROUNDUP((K9+L9+M9)*(1+Summary!$C$9)/100,0)/10 -> 0.9 | O9: Orange +12 V; wht/org GND; green ESP32 TX -> P4 RX; wht/grn P4 TX -> ESP32 RX; blue PIR out; wht/blu GND; brown HX711 SCK; wht/brn HX711 DOUT | P9: 12 V (not 5 V) goes over the cable; a mini buck in the vision box makes 5 V for the ESP32-P4 board and the PIR. The reward HX711 runs off the P4 board's 3.3 V pin. 8 conductors are enough. Cut both RJ45 plugs off.
A10: W09 | B10: Trapdoor servo | C10: MG996R in pit servo mount | D10: JB G2 (lower-left) | E10: 3-core 22 AWG round | F10: 3C22 | G10: 3 | H10: 22 | I10: 4.2 | J10: G2-LL | K10: 1051 | L10: 250 | M10: 150 | N10: =ROUNDUP((K10+L10+M10)*(1+Summary!$C$9)/100,0)/10 -> 1.6 | O10: as W01 | P10: Up the back-left corner through the battery-shelf notch.
A11: W10 | B11: Pit load cell | C11: Pit load cell (on the trapdoor) | D11: HX711 #2 in JB, G2 (upper-left) | E11: 4-core 24 AWG shielded (foil + drain) | F11: 4C24S | G11: 4 | H11: 24 | I11: 4.6 | J11: G2-UL | K11: 1174 | L11: 250 | M11: 250 | N11: =ROUNDUP((K11+L11+M11)*(1+Summary!$C$9)/100,0)/10 -> 1.9 | O11: Red E+, black E-, green A+, white A- (match the cell's colors); drain -> HX711 GND at the JB end only | P11: Leave a 10 cm service loop where it leaves the moving trapdoor (included in the 250 mm end slack). Shielded because it runs next to the solenoid and servo leads.
A12: W11 | B12: Trapdoor solenoid | C12: Solenoid (+X end) | D12: JB G2 (lower-right) | E12: 2-core 20 AWG round | F12: 2C20 | G12: 2 | H12: 20 | I12: 4.3 | J12: G2-LR | K12: 1093 | L12: 250 | M12: 150 | N12: =ROUNDUP((K12+L12+M12)*(1+Summary!$C$9)/100,0)/10 -> 1.7 | O12: Red +12 V; black -> MOSFET module OUT- | P12: 1N4007 across the coil (band to +), at the solenoid.
A13: W12 | B13: Pit light ring | C13: COB strip on the light ring (through lining hole) | D13: JB G2 (upper-right) | E13: 2-core 20 AWG round | F13: 2C20 | G13: 2 | H13: 20 | I13: 4.3 | J13: G2-UR | K13: 971 | L13: 250 | M13: 150 | N13: =ROUNDUP((K13+L13+M13)*(1+Summary!$C$9)/100,0)/10 -> 1.6 | O13: Red +12 V; black -> MOSFET module OUT- | P13: 12 V COB strip, ~45 cm.
... A17: W15b | B17: Fuse 1 to controller BAT+ | C17: Fuse 1 holder | D17: Controller BAT+ | E17: 16 AWG red | F17: 16AWG | G17: 1 | H17: 16 | I17: 3.2 | J17: - | K17: 122 | L17: 0 | M17: 100 | N17: =ROUNDUP((K17+L17+M17)*(1+Summary!$C$9)/100,0)/10 -> 0.3 | O17: + | P17: Until Phase 9: fuse 1 feeds W13 directly.
A18: W16 | B18: Battery - to controller BAT- | C18: Battery - (F2 spade) | D18: Controller BAT- | E18: 16 AWG black | F18: 16AWG | G18: 1 | H18: 16 | I18: 3.2 | J18: - | K18: 167 | L18: 0 | M18: 100 | N18: =ROUNDUP((K18+L18+M18)*(1+Summary!$C$9)/100,0)/10 -> 0.3 | O18: -
A19: W17 | B19: PIR | C19: AM312 header (back of PIR housing) | D19: Vision box PG7 #1 (front) | E19: 3-core 22 AWG round | F19: 3C22 | G19: 3 | H19: 22 | I19: 4.2 | J19: VB PG7-1 | K19: 81 | L19: 100 | M19: 100 | N19: =ROUNDUP((K19+L19+M19)*(1+Summary!$C$9)/100,0)/10 -> 0.4 | O19: VCC (+5 V from vision-box buck), GND, OUT | P19: Through the bottom plate's 8 mm hole at (0, -80). Dupont 3-pin housing at the PIR.
A20: W18 | B20: Reward load cell | C20: Load cell fixed end | D20: HX711 #1 in vision box, PG7 #2 (front) | E20: cell's own 4 leads in heat-shrink | F20: STOCK | G20: 4 | H20: 30 | I20: 3.5 | J20: VB PG7-2 | K20: 111 | L20: 100 | M20: 50 | N20: =ROUNDUP((K20+L20+M20)*(1+Summary!$C$9)/100,0)/10 -> 0.3 | O20: Red E+, black E-, green A+, white A- | P20: Stock leads (~20 cm) just reach; extend with 4-core shielded leftovers if short. Through the plate's 8 mm hole at (-75, -60).
A22: Buy length = (route + inside-box run + end slack) x (1 + cable spare on Summary), rounded up to 0.1 m. Route lengths are measured along the modeled tubes in CrowBox_Wiring_v2.step.
A24: Totals by cable type
E25: Type key | F25: Buy as | G25: Total (m)
E26: 3C22 | F26: 3-core 22 AWG round | G26: =SUMIF($F$2:$F$20,"3C22",$N$2:$N$20) -> 5.6
E27: 2C20 | F27: 2-core 20 AWG round | G27: =SUMIF($F$2:$F$20,"2C20",$N$2:$N$20) -> 5.9
E28: 6C24 | F28: 6-core 24 AWG round | G28: =SUMIFS($N$2:$N$20,$F$2:$F$20,"6C24",$A$2:$A$20,"<>W04") -> 1.2
E29: 4C24S | F29: 4-core 24 AWG shielded | G29: =SUMIF($F$2:$F$20,"4C24S",$N$2:$N$20) -> 1.9
E30: CAT6 | F30: Cat6 stranded patch | G30: =SUMIF($F$2:$F$20,"CAT6",$N$2:$N$20) -> 0.9
E31: 2C16 | F31: 2-core 16 AWG round | G31: =SUMIF($F$2:$F$20,"2C16",$N$2:$N$20) -> 1.3
E32: 2C18UV | F32: 2-core 18 AWG UV (solar) | G32: =SUMIF($F$2:$F$20,"2C18UV",$N$2:$N$20) -> 1.3
E33: 16AWG | F33: 16 AWG red/black | G33: =SUMIF($F$2:$F$20,"16AWG",$N$2:$N$20) -> 0.8
E34: 6C24 (W04) | F34: 6-core for the paused IR run | G34: =SUMIFS($N$2:$N$20,$A$2:$A$20,"W04") -> 1.5

Sheet Glands
A1: Where | B1: Gland | C1: Hole / insert position | D1: Cable | E1: Position (model, mm) | F1: Drill | G1: Notes
A2: Junction box back face | B2: G1 PG16, 4-hole insert (4 x 5 mm) | C2: upper-left | D2: W04 IR beams (PAUSED - plug it) | E2: X -41, Z 360 | F2: 22.5-23 mm | G2: All JB glands sit in one low row so the mounting plate keeps the top 2/3 of the box.
C3: upper-right | D3: W01 doser servo 1
C4: lower-left | D4: W05 gate actuator L
C5: lower-right | D5: W02 doser servo 2
A6: Junction box back face | B6: G2 PG16, 4-hole insert (4 x 5 mm) | C6: upper-left | D6: W10 pit load cell (shielded) | E6: X -5, Z 360 | F6: 22.5-23 mm
C7: upper-right | D7: W12 pit light ring
C8: lower-left | D8: W09 trapdoor servo
C9: lower-right | D9: W11 solenoid
A10: Junction box back face | B10: G3 PG16, 4-hole insert (4 x 5 mm) | C10: upper-left | D10: W03 doser servo 3 | E10: X 31, Z 360 | F10: 22.5-23 mm
C11: upper-right | D11: spare (plug it)
C12: lower-left | D12: W07 signal pod
C13: lower-right | D13: W06 gate actuator R
A14: Junction box back face | B14: G4 PG9 (4-8 mm) | C14: single | D14: W08 vision box Cat6 | E14: X -23, Z 395 | F14: 15.5 mm
A15: Junction box back face | B15: G5 PG9 (4-8 mm) | C15: single | D15: W13 12 V power in | E15: X 13, Z 395 | F15: 15.5 mm | G15: 16/2 cable must be <= 7.5 mm OD.
A16: Back panel | B16: gland window 106 x 65, r6 corners | C16: - | D16: all of the above | E16: X -58..48, Z 343..408 | F16: jigsaw | G16: Replaces the four separate 34/26 mm holes (they would leave 2 mm webs). Run a bead of neutral-cure silicone around the JB back face.
A17: Vision box front wall | B17: PG7 #1 | C17: single | D17: W17 PIR | E17: X +12, Z 262 | F17: 12.5-13 mm | G17: Drill the base walls, never the lid.
A18: Vision box front wall | B18: PG7 #2 | C18: single | D18: W18 reward load cell leads | E18: X -12, Z 262 | F18: 12.5-13 mm | G18: 4 thin leads: slide a heat-shrink sleeve over them so the seal grips.
A19: Vision box back wall | B19: PG9 | C19: single | D19: W08 Cat6 | E19: X -25, Z 258 | F19: 15.5 mm
A20: Roof | B20: PG7 (already modeled) | C20: single | D20: W14 solar | E20: X 205, Y 250 | F20: 12.5-13 mm | G20: Phase 9.
A21: Bay floor, back-left | B21: 16 mm hole (no grommet) | C21: - | D21: W01, W02, W04 | E21: X -208, Y 250 | F21: 16 mm | G21: Rubber grommets don't fit 6 mm ply; sand the edge and wrap the cables with split loom at the hole.
A22: Bay floor, back-right | B22: 16 mm hole (no grommet) | C22: - | D22: W03, W14 | E22: X 208, Y 250 | F22: 16 mm
A23: Bottom plate | B23: 8 mm holes (already modeled) | C23: - | D23: W17 at (0,-80), W18 at (-75,-60) | F23: 8 mm | G23: Deburr; heat-shrink sleeve on the cable where it passes.
A24: Battery shelf notches | B24: back-left / back-right | C24: - | D24: left: W09, W10 right: W11, W12 | F24: - | G24: Pit cables go under the shelf and rise through the corner notches.
A26: Multi-hole inserts seal 4.5-5.5 mm cable. Build up thinner cable (the 4.2 mm servo cable) with one layer of heat-shrink where it passes the seal. Plug unused holes with a 5 mm rod or a short M5 screw.

Sheet Print
A1: Part | B1: Source | C1: Qty | D1: Material | E1: Color | F1: Solid vol each (cm3) | G1: Density (g/cm3) | H1: Fill factor | I1: Grams (all) | J1: Size (mm) | K1: How to print | L1: Status | M1: Notes
A2: Signal pod (LEDs + buzzer) | B2: CrowBox_SignalPod_print.step (new) | C2: 1 | D2: ASA | E2: black | F2: 25.1 | G2: 1.07 | H2: 0.85 | I2: =C2*F2*G2*H2 -> 22.82845 | J2: 58 x 53 x 22 | K2: Stand it on the nose tip (front face down): LED bores vertical, no supports. 3 walls, 30%. | L2: Modeled (new) | M2: Nose sits in the PIR slot, so it gets sun: ASA.
A3: Perch bracket L | B3: CrowBox_Perch_D.step | C3: 1 | D3: ASA | E3: any | F3: 219.3 | G3: 1.07 | H3: 0.55 | I3: =C3*F3*G3*H3 -> 129.05805 | J3: 46 x 139 x 165 | K3: On its outer side face so the rod holes print vertical. 4 walls, 30% gyroid. | L3: Modeled | M3: Outside, in the sun, carries the crow: ASA.
A4: Perch bracket R | B4: CrowBox_Perch_D.step | C4: 1 | D4: ASA | E4: any | F4: 219.3 | G4: 1.07 | H4: 0.55 | I4: =C4*F4*G4*H4 -> 129.05805 | J4: 46 x 139 x 165 | K4: as L | L4: Modeled
A5: Chute bracket 35 deg | B5: CrowBox_ChuteBracket_35deg.step | C5: 1 | D5: PETG | E5: any | F5: 67.4 | G5: 1.27 | H5: 0.6 | I5: =C5*F5*G5*H5 -> 51.3588 | J5: 100 x 160 x 116 | K5: Base down. 3 walls, 25%. | L5: Modeled | M5: Inside the box: PETG is fine.
A6: Pit light ring | B6: CrowBox_PitLining_LightRing.step | C6: 1 | D6: PETG | E6: white | F6: 92.6 | G6: 1.27 | H6: 0.6 | I6: =C6*F6*G6*H6 -> 70.5612 | J6: 180 x 180 x 18.5 | K6: Lip down. 3 walls, 20%. | L6: Modeled | M6: White reflects the strip's light into the pit.
A7: PIR housing v2 | B7: CrowBox_PIR_Housing_v2.step (your part) | C7: 1 | D7: PETG | E7: black | F7: 12.3 | G7: 1.27 | H7: 0.9 | I7: =C7*F7*G7*H7 -> 14.0589 | J7: 91 x 30 x 25 | K7: Floor down. | L7: Modeled | M7: Lower it 0.8 mm in the model (it floats above the plate).
A8: Hopper cradle | B8: your Cradle part | C8: 3 | D8: PETG | E8: any | F8: 35.7 | G8: 1.27 | H8: 0.85 | I8: =C8*F8*G8*H8 -> 115.61445 | J8: 93 x 68 x 100 | K8: Foot down. | L8: Modeled | M8: Servo holes are 2.5 mm: use the MG996R's own screws.
A9: Doser rotor (60 mm notched) | B9: rotor_60mm.step (earlier draft) | C9: 3 | D9: PETG | E9: any | F9: 99.8 | G9: 1.27 | H9: 0.55 | I9: =C9*F9*G9*H9 -> 209.1309 | J9: 60 x 60 x 38 | K9: Servo face down. 4 walls, 40%. | L9: NOT in the assembly | M9: Re-check against the MG996R shaft position (Z ~612) before printing.
A10: Pit servo mount | B10: your servo_mount part | C10: 1 | D10: PETG | E10: any | F10: 108.4 | G10: 1.27 | H10: 0.55 | I10: =C10*F10*G10*H10 -> 75.7174 | J10: 74 x 49 x 36 | L10: Modeled
A11: Solenoid mount | B11: your solenoid_mount part | C11: 1 | D11: PETG | E11: any | F11: 15.5 | G11: 1.27 | H11: 0.9 | I11: =C11*F11*G11*H11 -> 17.7165 | J11: 54 x 44 x 22 | L11: Modeled
A12: Trapdoor frame (?) | B12: your Trapdoor part | C12: 1 | D12: PETG | E12: any | F12: 150.8 | G12: 1.27 | H12: 0.55 | I12: =C12*F12*G12*H12 -> 105.3338 | J12: 218 x 148 x 30 | K12: Needs a 220+ mm bed. | L12: Modeled | M12: Print or cut? - your call.
A13: Trapdoor top plate (?) | B13: your top_door part | C13: 1 | D13: PETG | E13: any | F13: 172.9 | G13: 1.27 | H13: 0.5 | I13: =C13*F13*G13*H13 -> 109.7915 | J13: 148 x 148 x 8 | L13: Modeled | M13: Could be 6 mm ply or acrylic instead.
A14: Chute (?) | B14: your Chute_new part | C14: 1 | D14: PETG | E14: any | F14: 44.7 | G14: 1.27 | H14: 0.95 | I14: =C14*F14*G14*H14 -> 53.93055 | J14: 105 x 372 x 204 | K14: Too long for most beds (~424 mm along the slope). | L14: Modeled | M14: Split in 2 halves, or bend it from 0.040in 5052 at SendCutSend.
A16: Filament totals
A17: PETG | H17: grams: | I17: =SUMIF($D$2:$D$14,"PETG",$I$2:$I$14)*(1+Summary!$C$10) -> 946.6961 | J17: 1 kg spools: | K17: =ROUNDUP(I17/1000,0) -> 1
A18: ASA | H18: grams: | I18: =SUMIF($D$2:$D$14,"ASA",$I$2:$I$14)*(1+Summary!$C$10) -> 323.08623 | J18: 1 kg spools: | K18: =ROUNDUP(I18/1000,0) -> 1
A20: Grams = qty x solid volume x density x fill factor (fill factor ~0.5-0.6 for chunky parts at 3-4 walls / 25-40% infill, ~0.85-0.95 for thin-walled parts) x (1 + print-waste allowance on Summary). No PLA: it creeps in summer sun.

Sheet Cut
A1: Part | B1: Material / stock | C1: Thickness | D1: Finished size (mm) | E1: Qty | F1: Process | G1: Source file | H1: Notes
A2: A. SendCutSend (order these cut) - cost is on the Buy tab
A3: Reward tray | B3: 5052-H32 aluminum | C3: 0.080" (2.03 mm) | D3: 376 x 79 x 50 (bent) | E3: 1 | F3: laser + 3 bends | G3: CrowBox_RewardTray_5052_0p080_v2.step | H3: As modeled.
A4: Reward bottom plate | B4: 5052-H32 aluminum | C4: 0.187" (4.75 mm) | D4: 450 x 95 | E4: 1 | F4: laser | G4: CrowBox_RewardBottomPlate_v3.step | H4: SCS has no 4 mm 5052. Order 0.187in: top stays at Z 280, the extra 0.75 mm goes down, gap to the front bar drops to 0.25 mm, so skip the 1 mm shims.
A5: Gate | B5: Polycarbonate (clear) | C5: 0.177" (4.5 mm) | D5: 457.7 x 95 | E5: 1 | F5: CNC routed | G5: export from your Gate body | H5: Model is 4 mm; SCS polycarbonate comes in 3.0 / 4.5 / 5.6 mm. 4.5 mm still slides in the 6.2 mm slots.
A6: OPTION: clear front panel | B6: Polycarbonate (clear) | C6: 0.220" (5.6 mm) | D6: 502 x 1100 | E6: 1 | F6: CNC routed | G6: FrontPanel_6mm in Panels_v3 | H6: Only if you go clear. Fits SCS's 30 x 44 in limit. Keep the PIR slot open; paint/opaque film over the pit zone.
A8: B. Wood (cut at home or have the store rip the sheets)
A9: Side panel L / R | B9: Sheet A: 1/4in exterior ply 4x8 | C9: 6 mm | D9: 425 x 1100 | E9: 2 | F9: circular saw + drill | G9: CrowBox_Panels_v3.step | H9: Sheet A row 1: side + back; row 2: side + front (1100 along the 8 ft side).
A10: Back panel | B10: Sheet A | C10: 6 mm | D10: 490 x 1100 | E10: 1 | F10: saw + jigsaw (gland window) | G10: CrowBox_Panels_v3.step | H10: v3: gland window 106 x 65 behind the JB; JB mount holes; no Z 360 holes.
A11: Front panel | B11: Sheet A | C11: 6 mm | D11: 502 x 1100 | E11: 1 | F11: saw + jigsaw (3 windows) | G11: CrowBox_Panels_v3.step | H11: Windows: reward 160 x 44, PIR slot 190 x 16, object 120 x 60.
A12: Roof | B12: Sheet B: 1/4in ply 2x4 project panel | C12: 6 mm | D12: 522 x 452 | E12: 1 | F12: saw + drill | G12: CrowBox_Roof_Solar.step | H12: Sheet B along the 4 ft side: roof 452 + bay floor 418 + shelf 148 = 1018 mm.
A13: Bay floor v2 | B13: Sheet B | C13: 6 mm | D13: 486 x 418 | E13: 1 | F13: saw + jigsaw (chute slot) | G13: CrowBox_BayFloor_v2.step
A14: Battery shelf v2 | B14: Sheet B | C14: 6 mm | D14: 486 x 148 | E14: 1 | F14: saw + jigsaw (notches, strap slots) | G14: CrowBox_FieldModules.step | H14: v2 adds 4 x M5 holes into the bottom side bars + 2 x M4 for the controller.
A15: Pit lining | B15: 1/8in tempered hardboard 2x4 | C15: 3 mm | D15: 150 x 150 (2), 144 x 150 (2) | E15: 4 | F15: saw | G15: CrowBox_PitLining_LightRing.step | H15: Paint matte light grey. VHB to the pit bars.
A16: Legs | B16: 2x2 x 8 ft pressure-treated (38 x 38) | C16: - | D16: 38 x 38 x 960 | E16: 4 | F16: miter saw | G16: CrowBox_Legs_v2.step | H16: Boards 1-2: 960 + 960 + 502 each; board 3: 362 + 362.
A17: Ground aprons L / R | B17: 2x2 PT | C17: - | D17: 38 x 38 x 362 | E17: 2 | F17: miter saw | G17: CrowBox_Legs_v2.step
A18: Ground apron back + raised front apron | B18: 2x2 PT | C18: - | D18: 38 x 38 x 502 | E18: 2 | F18: miter saw | G18: CrowBox_Legs_v2.step
A19: Diagonals L / R | B19: 1x2 x 8 ft (19 x 38) | C19: - | D19: ~660 (angle-cut to fit) | E19: 2 | F19: miter saw | G19: CrowBox_Legs_v2.step | H19: One 8 ft 1x2 gives 660 + 660 + 750 + scrap.
A20: Diagonal back | B20: 1x2 | C20: - | D20: ~750 (angle-cut to fit) | E20: 1 | F20: miter saw | G20: CrowBox_Legs_v2.step
A21: Skirt corner cleats | B21: 3/4in square dowel | C21: - | D21: 19 x 19 x 90 | E21: 4 | F21: saw | G21: CrowBox_Panels_v3.step
A22: Perch rods | B22: 1-1/4" hardwood dowel (31.75 mm) | C22: - | D22: 525 | E22: 2 | F22: saw | G22: CrowBox_Perch_D.step | H22: Not a 1-5/16in closet pole: it won't fit the printed brackets.
A24: C. 2020 extrusion cut list (from 1000 mm sticks, 3 mm kerf)
A25: Length (mm) | B25: Where | E25: Qty | F25: Total (mm)
A26: 1000 | B26: posts | E26: 4 | F26: =A26*E26 -> 4000
A27: 490 | B27: full-width crossbars (bottom front/back, reward level x3) | E27: 5 | F27: =A27*E27 -> 2450
A28: 450 | B28: between-post bars (reward back, bay x2, roof front/back) | E28: 5 | F28: =A28*E28 -> 2250
A29: 380 | B29: side bars (bottom, reward, bay, roof) x2 sides | E29: 8 | F29: =A29*E29 -> 3040
A30: 170 | B30: pit corner verticals | E30: 4 | F30: =A30*E30 -> 680
A31: 150 | B31: pit top/bottom rings + 1 under the solenoid side | E31: 9 | F31: =A31*E31 -> 1350
A32: Total | E32: =SUM(E26:E31) -> 35 | F32: =SUM(F26:F31) -> 13770
A33: 1000 mm sticks needed | E33: 15 | F33: Plan: 4 x [1000]; 2 x [490+490]; [490+450]; 2 x [450+450]; 2 x [380+380+170]; 2 x [380+380+150]; [170+170+150x4]; [150x3]
A34: Counts are after removing the duplicate pit bars in the model (see Model fixes): 4 x 150 removed. Square, deburred ends matter more than exact length; a miter saw with a non-ferrous blade, or order cut-to-length.

Sheet Buy
A1: ID | B1: Section | C1: Item | D1: Spec / part no. | E1: Need | F1: Unit | G1: Pack size | H1: Packs | I1: $ / pack (est.) | J1: Line $ | K1: Have? (Y = received, O = ordered) | L1: Still to buy $ | M1: Phase | N1: Used for | O1: Notes / price basis
A2: F01 | B2: Frame | C2: 2020 T-slot extrusion, 1000 mm | D2: 20x20, 6 mm slot (M5), 10-pack | E2: =Cut!$E$33 -> 15 | F2: sticks | G2: 10 | H2: =ROUNDUP(E2/G2,0) -> 2 | I2: 66.9 | J2: =H2*I2 -> 133.8 | K2: O | L2: =IF(OR(UPPER(K2)="Y",UPPER(K2)="O"),0,J2) -> 133.8 | M2: Build | N2: 35 bars, cut list on Cut tab | O2: VEVOR 10 x 1000 mm, vevor.com $65.90-66.90 (Oct 2026). Or order cut-to-length.
A3: F02 | B3: Frame | C3: 2020 corner bracket kit | D3: cast 20x28x28 ('2028') with M5 screws + T-nuts, 40 sets | E3: 78 | F3: brackets | G3: 40 | H3: =ROUNDUP(E3/G3,0) -> 2 | I3: 22 | J3: =H3*I3 -> 44 | K3: Y | L3: =IF(OR(UPPER(K3)="Y",UPPER(K3)="O"),0,J3) -> 44 | M3: Build | N3: 70 positions in the model + 8 under the roof top bars | O3: Model uses McMaster 5537T935 (~$5-6 each, ~$430 for 78). Generic is 2 mm bigger: check the bay-floor corner notches. est. US retail Oct 2026
A4: F03 | B4: Frame | C4: M5 drop-in T-nut | D4: for 2020 / 6 mm slot | E4: =SUMIF(Fasteners!$A$2:$A$41,"M5 T-nut",Fasteners!$C$2:$C$41) -> 150 | F4: pcs | G4: 100 | H4: =ROUNDUP(E4*(1+Summary!$C$8)/G4,0) -> 2 | I4: 9 | J4: =H4*I4 -> 18 | K4: Y | L4: =IF(OR(UPPER(K4)="Y",UPPER(K4)="O"),0,J4) -> 18 | M4: Build | N4: everything screwed into a slot (not brackets) | O4: est. US retail Oct 2026
A5: X01 | B5: Fasteners | C5: M5 x 8 button head | D5: ISO 7380, A2 stainless | E5: =SUMIF(Fasteners!$A$2:$A$41,"M5x8 BHCS",Fasteners!$C$2:$C$41) -> 8 | F5: pcs | G5: 50 | H5: =ROUNDUP(E5*(1+Summary!$C$8)/G5,0) -> 1 | I5: 7 | J5: =H5*I5 -> 7 | K5: O | L5: =IF(OR(UPPER(K5)="Y",UPPER(K5)="O"),0,J5) -> 7 | M5: Build | N5: light ring, vision box ears | O5: est. US retail Oct 2026
A6: X02 | B6: Fasteners | C6: M5 x 10 button head | D6: ISO 7380, A2 | E6: =SUMIF(Fasteners!$A$2:$A$41,"M5x10 BHCS",Fasteners!$C$2:$C$41) -> 17 | F6: pcs | G6: 50 | H6: =ROUNDUP(E6*(1+Summary!$C$8)/G6,0) -> 1 | I6: 7 | J6: =H6*I6 -> 7 | K6: O | L6: =IF(OR(UPPER(K6)="Y",UPPER(K6)="O"),0,J6) -> 7 | M6: Build | N6: bottom plate, chute bracket | O6: est. US retail Oct 2026
A7: X03 | B7: Fasteners | C7: M5 x 12 button head | D7: ISO 7380, A2 | E7: =SUMIF(Fasteners!$A$2:$A$41,"M5x12 BHCS",Fasteners!$C$2:$C$41) -> 82 | F7: pcs | G7: 100 | H7: =ROUNDUP(E7*(1+Summary!$C$8)/G7,0) -> 1 | I7: 11 | J7: =H7*I7 -> 11 | K7: O | L7: =IF(OR(UPPER(K7)="Y",UPPER(K7)="O"),0,J7) -> 11 | M7: Build | N7: panels, roof, bay floor, shelf, PIR housing | O7: est. US retail Oct 2026
A8: X04 | B8: Fasteners | C8: M5 x 16 button head | D8: ISO 7380, A2 | E8: =SUMIF(Fasteners!$A$2:$A$41,"M5x16 BHCS",Fasteners!$C$2:$C$41) -> 23 | F8: pcs | G8: 50 | H8: =ROUNDUP(E8*(1+Summary!$C$8)/G8,0) -> 1 | I8: 8 | J8: =H8*I8 -> 8 | K8: O | L8: =IF(OR(UPPER(K8)="Y",UPPER(K8)="O"),0,J8) -> 8 | M8: Build | N8: front panel, solar feet, pod, JB top | O8: est. US retail Oct 2026
A9: X05 | B9: Fasteners | C9: M5 x 20 button head | D9: ISO 7380, A2 | E9: =SUMIF(Fasteners!$A$2:$A$41,"M5x20 BHCS",Fasteners!$C$2:$C$41) -> 2 | F9: pcs | G9: 25 | H9: =ROUNDUP(E9*(1+Summary!$C$8)/G9,0) -> 1 | I9: 6 | J9: =H9*I9 -> 6 | K9: O | L9: =IF(OR(UPPER(K9)="Y",UPPER(K9)="O"),0,J9) -> 6 | M9: Build | N9: JB bottom bolts | O9: est. US retail Oct 2026
A10: X06 | B10: Fasteners | C10: M5 x 25 flanged button head | D10: ISO 7380-2, A2 | E10: =SUMIF(Fasteners!$A$2:$A$41,"M5x25 flanged BHCS",Fasteners!$C$2:$C$41) -> 4 | F10: pcs | G10: 20 | H10: =ROUNDUP(E10*(1+Summary!$C$8)/G10,0) -> 1 | I10: 8 | J10: =H10*I10 -> 8 | K10: O | L10: =IF(OR(UPPER(K10)="Y",UPPER(K10)="O"),0,J10) -> 8 | M10: Build | N10: perch brackets | O10: est. US retail Oct 2026
A11: X07 | B11: Fasteners | C11: M5 x 50 button or socket head | D11: A2 | E11: =SUMIF(Fasteners!$A$2:$A$41,"M5x50 BHCS",Fasteners!$C$2:$C$41) -> 12 | F11: pcs | G11: 25 | H11: =ROUNDUP(E11*(1+Summary!$C$8)/G11,0) -> 1 | I11: 10 | J11: =H11*I11 -> 10 | K11: O | L11: =IF(OR(UPPER(K11)="Y",UPPER(K11)="O"),0,J11) -> 10 | M11: Build | N11: legs to posts | O11: est. US retail Oct 2026
A12: X08 | B12: Fasteners | C12: M5 x 75 hex bolt | D12: A2, part-thread OK | E12: =SUMIF(Fasteners!$A$2:$A$41,"M5x75 hex bolt",Fasteners!$C$2:$C$41) -> 4 | F12: pcs | G12: 10 | H12: =ROUNDUP(E12*(1+Summary!$C$8)/G12,0) -> 1 | I12: 8 | J12: =H12*I12 -> 8 | L12: =IF(OR(UPPER(K12)="Y",UPPER(K12)="O"),0,J12) -> 8 | M12: Build | N12: skirt bolts | O12: est. US retail Oct 2026
A13: X09 | B13: Fasteners | C13: M5 flat washer | D13: ISO 7089, 10 mm OD, A2 | E13: =SUMIF(Fasteners!$A$2:$A$41,"M5 washer",Fasteners!$C$2:$C$41) -> 104 | F13: pcs | G13: 200 | H13: =ROUNDUP(E13*(1+Summary!$C$8)/G13,0) -> 1 | I13: 8 | J13: =H13*I13 -> 8 | K13: O | L13: =IF(OR(UPPER(K13)="Y",UPPER(K13)="O"),0,J13) -> 8 | M13: Build | N13: under heads on plywood | O13: est. US retail Oct 2026
A14: X10 | B14: Fasteners | C14: M5 fender washer | D14: 5.3 x 20 mm, A2 | E14: =SUMIF(Fasteners!$A$2:$A$41,"M5 fender washer",Fasteners!$C$2:$C$41) -> 20 | F14: pcs | G14: 25 | H14: =ROUNDUP(E14*(1+Summary!$C$8)/G14,0) -> 1 | I14: 6 | J14: =H14*I14 -> 6 | K14: O | L14: =IF(OR(UPPER(K14)="Y",UPPER(K14)="O"),0,J14) -> 6 | M14: Build | N14: legs, skirt bolts | O14: est. US retail Oct 2026
A15: X11 | B15: Fasteners | C15: M5 nylon-insert lock nut | D15: A2 | E15: =SUMIF(Fasteners!$A$2:$A$41,"M5 nyloc",Fasteners!$C$2:$C$41) -> 6 | F15: pcs | G15: 50 | H15: =ROUNDUP(E15*(1+Summary!$C$8)/G15,0) -> 1 | I15: 5 | J15: =H15*I15 -> 5 | K15: O | L15: =IF(OR(UPPER(K15)="Y",UPPER(K15)="O"),0,J15) -> 5 | M15: Build | N15: JB bottom, skirt bolts | O15: est. US retail Oct 2026
A16: X12 | B16: Fasteners | C16: M5 hex nut | D16: A2, 8 mm AF | E16: =SUMIF(Fasteners!$A$2:$A$41,"M5 hex nut",Fasteners!$C$2:$C$41) -> 4 | F16: pcs | G16: 50 | H16: =ROUNDUP(E16*(1+Summary!$C$8)/G16,0) -> 1 | I16: 4 | J16: =H16*I16 -> 4 | K16: O | L16: =IF(OR(UPPER(K16)="Y",UPPER(K16)="O"),0,J16) -> 4 | M16: Build | N16: chute to bracket | O16: est. US retail Oct 2026
A17: X13 | B17: Fasteners | C17: M5 unthreaded spacer, 5 mm long | D17: ~10 mm OD, nylon or aluminum | E17: 0 | F17: pcs | G17: 25 | H17: =ROUNDUP(E17*(1+Summary!$C$8)/G17,0) -> 1 | I17: 8 | J17: =H17*I17 -> 8 | L17: =IF(OR(UPPER(K17)="Y",UPPER(K17)="O"),0,J17) -> 8 | M17: Build | N17: front panel standoffs | O17: DROPPED: front panel standoffs are stacks of 5 M5 washers instead.
A18: X14 | B18: Fasteners | C18: M4 x 16 button head | D18: ISO 7380, A2 | E18: =SUMIF(Fasteners!$A$2:$A$41,"M4x16 BHCS",Fasteners!$C$2:$C$41) -> 4 | F18: pcs | G18: 25 | H18: =ROUNDUP(E18*(1+Summary!$C$8)/G18,0) -> 1 | I18: 5 | J18: =H18*I18 -> 5 | K18: O | L18: =IF(OR(UPPER(K18)="Y",UPPER(K18)="O"),0,J18) -> 5 | M18: Build | N18: load cell fixed end, controller | O18: est. US retail Oct 2026
A19: X15 | B19: Fasteners | C19: M4 x 20 button head | D19: ISO 7380, A2 | E19: =SUMIF(Fasteners!$A$2:$A$41,"M4x20 BHCS",Fasteners!$C$2:$C$41) -> 8 | F19: pcs | G19: 25 | H19: =ROUNDUP(E19*(1+Summary!$C$8)/G19,0) -> 1 | I19: 5 | J19: =H19*I19 -> 5 | K19: O | L19: =IF(OR(UPPER(K19)="Y",UPPER(K19)="O"),0,J19) -> 5 | M19: Build | N19: tray to load cell, cradles | O19: est. US retail Oct 2026
A20: X16 | B20: Fasteners | C20: M4 nylon-insert lock nut | D20: A2 | E20: =SUMIF(Fasteners!$A$2:$A$41,"M4 nyloc",Fasteners!$C$2:$C$41) -> 8 | F20: pcs | G20: 50 | H20: =ROUNDUP(E20*(1+Summary!$C$8)/G20,0) -> 1 | I20: 4 | J20: =H20*I20 -> 4 | K20: O | L20: =IF(OR(UPPER(K20)="Y",UPPER(K20)="O"),0,J20) -> 4 | M20: Build | N20: cradles, controller | O20: est. US retail Oct 2026
A21: X17 | B21: Fasteners | C21: M4 flat washer | D21: A2 | E21: =SUMIF(Fasteners!$A$2:$A$41,"M4 washer",Fasteners!$C$2:$C$41) -> 20 | F21: pcs | G21: 100 | H21: =ROUNDUP(E21*(1+Summary!$C$8)/G21,0) -> 1 | I21: 4 | J21: =H21*I21 -> 4 | K21: O | L21: =IF(OR(UPPER(K21)="Y",UPPER(K21)="O"),0,J21) -> 4 | M21: Build | N21: load cell, cradles, controller | O21: est. US retail Oct 2026
A22: X18 | B22: Fasteners | C22: Spacer M4 x 11 mm | D22: McMaster 92871A311 (18-8) | E22: 0 | F22: pcs | G22: 1 | H22: =ROUNDUP(E22/G22,0) -> 2 | I22: 2.5 | J22: =H22*I22 -> 5 | L22: =IF(OR(UPPER(K22)="Y",UPPER(K22)="O"),0,J22) -> 5 | M22: Build | N22: tray to load cell | O22: DROPPED: load cell spacer is 3 M4 hex nuts + 3 M4 washers instead.
A23: X19 | B23: Fasteners | C23: Spacer M4 x 5 mm | D23: McMaster 92871A008 (18-8) | E23: 0 | F23: pcs | G23: 1 | H23: =ROUNDUP(E23/G23,0) -> 2 | I23: 2 | J23: =H23*I23 -> 4 | L23: =IF(OR(UPPER(K23)="Y",UPPER(K23)="O"),0,J23) -> 4 | M23: Build | N23: load cell fixed end | O23: DROPPED: load cell spacer is 6 M4 washers instead.
A24: X20 | B24: Fasteners | C24: #8 x 2-1/2in exterior screw | D24: coated deck screw | E24: =SUMIF(Fasteners!$A$2:$A$41,"#8x2-1/2 wood",Fasteners!$C$2:$C$41) -> 16 | F24: pcs | G24: 50 | H24: =ROUNDUP(E24*(1+Summary!$C$8)/G24,0) -> 1 | I24: 8 | J24: =H24*I24 -> 8 | L24: =IF(OR(UPPER(K24)="Y",UPPER(K24)="O"),0,J24) -> 8 | M24: Build | N24: aprons | O24: est. US retail Oct 2026
A25: X21 | B25: Fasteners | C25: #8 x 1-1/4in exterior screw | D25: coated | E25: =SUMIF(Fasteners!$A$2:$A$41,"#8x1-1/4 wood",Fasteners!$C$2:$C$41) -> 12 | F25: pcs | G25: 50 | H25: =ROUNDUP(E25*(1+Summary!$C$8)/G25,0) -> 1 | I25: 6 | J25: =H25*I25 -> 6 | L25: =IF(OR(UPPER(K25)="Y",UPPER(K25)="O"),0,J25) -> 6 | M25: Build | N25: diagonals | O25: est. US retail Oct 2026
A26: X22 | B26: Fasteners | C26: #6 x 5/8in wood screw | D26: pan or flat head | E26: =SUMIF(Fasteners!$A$2:$A$41,"#6x5/8 wood",Fasteners!$C$2:$C$41) -> 16 | F26: pcs | G26: 50 | H26: =ROUNDUP(E26*(1+Summary!$C$8)/G26,0) -> 1 | I26: 5 | J26: =H26*I26 -> 5 | L26: =IF(OR(UPPER(K26)="Y",UPPER(K26)="O"),0,J26) -> 5 | M26: Build | N26: skirt cleats | O26: est. US retail Oct 2026
A27: X23 | B27: Fasteners | C27: #6 x 3/4in pan-head screw | E27: =SUMIF(Fasteners!$A$2:$A$41,"#6x3/4 wood",Fasteners!$C$2:$C$41) -> 4 | F27: pcs | G27: 25 | H27: =ROUNDUP(E27*(1+Summary!$C$8)/G27,0) -> 1 | I27: 4 | J27: =H27*I27 -> 4 | L27: =IF(OR(UPPER(K27)="Y",UPPER(K27)="O"),0,J27) -> 4 | M27: Build | N27: perch rod locks | O27: est. US retail Oct 2026
A28: X24 | B28: Fasteners | C28: Nylon standoff kit M2 / M2.5 / M3 | D28: standoffs + screws + nuts | E28: 1 | F28: kit | G28: 1 | H28: =ROUNDUP(E28/G28,0) -> 1 | I28: 12 | J28: =H28*I28 -> 12 | K28: Y | L28: =IF(OR(UPPER(K28)="Y",UPPER(K28)="O"),0,J28) -> 12 | M28: Build | N28: P4 board, camera, JB modules | O28: est. US retail Oct 2026
A29: X25 | B29: Fasteners | C29: Pit mechanism hardware (?) | D29: servo mount, solenoid mount, trapdoor hinge | E29: 1 | F29: lot | G29: 1 | H29: =ROUNDUP(E29/G29,0) -> 1 | I29: 8 | J29: =H29*I29 -> 8 | L29: =IF(OR(UPPER(K29)="Y",UPPER(K29)="O"),0,J29) -> 8 | M29: Build | N29: your pit design (not specified) | O29: placeholder
A30: X26 | B30: Fasteners | C30: Gate actuator clevis pins / rod-end jaws (?) | D30: M4, per your gate design | E30: 2 | F30: pcs | G30: 2 | H30: =ROUNDUP(E30/G30,0) -> 1 | I30: 10 | J30: =H30*I30 -> 10 | L30: =IF(OR(UPPER(K30)="Y",UPPER(K30)="O"),0,J30) -> 10 | M30: Build | N30: replace the clevis stand-ins | O30: placeholder
A31: S01 | B31: Wood & sheet | C31: 1/4in (6 mm) exterior-glue plywood, 4 x 8 ft | D31: BC sanded or similar | E31: 1 | F31: sheet | G31: 1 | H31: =ROUNDUP(E31/G31,0) -> 1 | I31: 42 | J31: =H31*I31 -> 42 | L31: =IF(OR(UPPER(K31)="Y",UPPER(K31)="O"),0,J31) -> 42 | M31: Build | N31: Sheet A: side x2, back, front | O31: est. US retail Oct 2026 (home center)
A32: S02 | B32: Wood & sheet | C32: 1/4in (6 mm) plywood, 2 x 4 ft project panel | E32: 1 | F32: sheet | G32: 1 | H32: =ROUNDUP(E32/G32,0) -> 1 | I32: 17 | J32: =H32*I32 -> 17 | L32: =IF(OR(UPPER(K32)="Y",UPPER(K32)="O"),0,J32) -> 17 | M32: Build | N32: Sheet B: roof, bay floor, battery shelf | O32: est. US retail Oct 2026
A33: S03 | B33: Wood & sheet | C33: 1/8in (3 mm) tempered hardboard, 2 x 4 ft | E33: 1 | F33: sheet | G33: 1 | H33: =ROUNDUP(E33/G33,0) -> 1 | I33: 9 | J33: =H33*I33 -> 9 | L33: =IF(OR(UPPER(K33)="Y",UPPER(K33)="O"),0,J33) -> 9 | M33: Build | N33: pit lining | O33: est. US retail Oct 2026
A34: S04 | B34: Wood & sheet | C34: 2x2 x 8 ft, pressure-treated | D34: actual 1.5 x 1.5 in (38 mm) | E34: 3 | F34: boards | G34: 1 | H34: =ROUNDUP(E34/G34,0) -> 3 | I34: 6 | J34: =H34*I34 -> 18 | L34: =IF(OR(UPPER(K34)="Y",UPPER(K34)="O"),0,J34) -> 18 | M34: Build | N34: legs + aprons (ground contact) | O34: est. US retail Oct 2026
A35: S05 | B35: Wood & sheet | C35: 1x2 x 8 ft | D35: actual 0.75 x 1.5 in | E35: 1 | F35: boards | G35: 1 | H35: =ROUNDUP(E35/G35,0) -> 1 | I35: 3 | J35: =H35*I35 -> 3 | L35: =IF(OR(UPPER(K35)="Y",UPPER(K35)="O"),0,J35) -> 3 | M35: Build | N35: diagonals | O35: est. US retail Oct 2026
A36: S06 | B36: Wood & sheet | C36: 3/4in square dowel, 36in | E36: 1 | F36: pcs | G36: 1 | H36: =ROUNDUP(E36/G36,0) -> 1 | I36: 3 | J36: =H36*I36 -> 3 | L36: =IF(OR(UPPER(K36)="Y",UPPER(K36)="O"),0,J36) -> 3 | M36: Build | N36: skirt corner cleats | O36: est. US retail Oct 2026
A37: S07 | B37: Wood & sheet | C37: 1-1/4in hardwood dowel, 48in | D37: 31.75 mm - not 1-5/16in closet pole | E37: 1 | F37: pcs | G37: 1 | H37: =ROUNDUP(E37/G37,0) -> 1 | I37: 12 | J37: =H37*I37 -> 12 | L37: =IF(OR(UPPER(K37)="Y",UPPER(K37)="O"),0,J37) -> 12 | M37: Build | N37: perch rods x2 | O37: est. US retail Oct 2026
A38: S08 | B38: Wood & sheet | C38: Exterior primer + paint, 1 qt | D38: or exterior sealer | E38: 1 | F38: qt | G38: 1 | H38: =ROUNDUP(E38/G38,0) -> 1 | I38: 20 | J38: =H38*I38 -> 20 | L38: =IF(OR(UPPER(K38)="Y",UPPER(K38)="O"),0,J38) -> 20 | M38: Build | N38: all wood | O38: est. US retail Oct 2026
A39: C01 | B39: Cut service | C39: Reward tray (SendCutSend) | D39: 5052-H32 0.080", 3 bends | E39: 1 | F39: part | G39: 1 | H39: =ROUNDUP(E39/G39,0) -> 1 | I39: 40 | J39: =H39*I39 -> 40 | L39: =IF(OR(UPPER(K39)="Y",UPPER(K39)="O"),0,J39) -> 40 | M39: Build | N39: reward tray | O39: est.; get the real quote by uploading the STEP
A40: C02 | B40: Cut service | C40: Reward bottom plate (SendCutSend) | D40: 5052-H32 0.187" | E40: 1 | F40: part | G40: 1 | H40: =ROUNDUP(E40/G40,0) -> 1 | I40: 32 | J40: =H40*I40 -> 32 | L40: =IF(OR(UPPER(K40)="Y",UPPER(K40)="O"),0,J40) -> 32 | M40: Build | N40: bottom plate v3 | O40: est.
...

Sheet Tooling
A1: Tool | B1: Needed for | C1: Est. $ | D1: Have? (Y) | E1: Still to buy $ | F1: Notes
A2: 3D printer, 220+ mm bed (?) | B2: printed parts; trapdoor frame is 218 mm | C2: 0 | E2: =IF(UPPER(D2)="Y",0,C2) -> 0 | F2: assumed owned
A3: Hex keys 2.5 / 3 / 4 mm | B3: M4 + M5 button heads, socket heads | C3: 8 | D3: Y | E3: =IF(UPPER(D3)="Y",0,C3) -> 8
A4: Cordless drill/driver (?) | B4: everything | C4: 0 | E4: =IF(UPPER(D4)="Y",0,C4) -> 0 | F4: assumed owned
A5: Drill bits: 4.5, 5.5, 8 mm + 1/8in pilot (?) | B5: M4/M5 clearance, cable holes, wood screws | C5: 12 | D5: Y | E5: =IF(UPPER(D5)="Y",0,C5) -> 12
A6: Step drill to 25 mm (?) | B6: gland holes 12.5 / 15.5 / 22.5-23 mm in the JB and vision box | C6: 18 | D6: Y | E6: =IF(UPPER(D6)="Y",0,C6) -> 18
A7: Jigsaw (?) | B7: front-panel windows, back-panel gland window, bay-floor chute slot | C7: 0 | E7: =IF(UPPER(D7)="Y",0,C7) -> 0 | F7: or a hole saw + file
A8: Circular saw or store rip cuts (?) | B8: plywood panels | C8: 0 | E8: =IF(UPPER(D8)="Y",0,C8) -> 0 | F8: home centers rip sheets free
A9: Miter saw + non-ferrous blade (?) | B9: 2020 extrusion (31 cuts), 2x2, 1x2 | C9: 30 | E9: =IF(UPPER(D9)="Y",0,C9) -> 30 | F9: blade price; or order the extrusion cut-to-length
A10: Deburring tool / file (?) | B10: extrusion ends, plate holes | C10: 8 | E10: =IF(UPPER(D10)="Y",0,C10) -> 8
A11: Soldering iron + solder + flux (?) | B11: servo headers, splices, LED leads | C11: 0 | E11: =IF(UPPER(D11)="Y",0,C11) -> 0 | F11: assumed owned
A12: Heat gun (?) | B12: heat-shrink, adhesive-lined splices | C12: 20 | E12: =IF(UPPER(D12)="Y",0,C12) -> 20
A13: Wire strippers 16-26 AWG (?) | B13: all cables | C13: 12 | D13: Y | E13: =IF(UPPER(D13)="Y",0,C13) -> 12
A14: Ferrule crimper (?) | B14: screw-terminal ends | C14: 18 | E14: =IF(UPPER(D14)="Y",0,C14) -> 18 | F14: often sold with the ferrule kit
A15: Dupont crimper (?) | B15: only if you crimp your own Dupont ends | C15: 22 | E15: =IF(UPPER(D15)="Y",0,C15) -> 22 | F15: skip with pre-crimped jumpers
A16: Multimeter (?) | B16: bucks, polarity, continuity | C16: 0 | D16: Y | E16: =IF(UPPER(D16)="Y",0,C16) -> 0 | F16: assumed owned
A17: Calipers (?) | B17: measure modules before finalizing (the doc asks for this) | C17: 15 | D17: Y | E17: =IF(UPPER(D17)="Y",0,C17) -> 15
A18: Clamps, square, tape measure | B18: panels, legs | C18: 0 | E18: =IF(UPPER(D18)="Y",0,C18) -> 0 | F18: assumed owned
A19: Paint brush / small roller | B19: plywood | C19: 8 | E19: =IF(UPPER(D19)="Y",0,C19) -> 8
A20: Micro-USB data cable | B20: flashing the ESP32 | C20: 5 | E20: =IF(UPPER(D20)="Y",0,C20) -> 5
A21: microSD reader (?) | B21: reading training photos off the P4's microSD | C21: 8 | E21: =IF(UPPER(D21)="Y",0,C21) -> 8
A23: Total | C23: =SUM(C2:C21) -> 184 | E23: =SUM(E2:E21) -> 184
A24: "?" = not sure you have it or need it. Items at $0 are assumed owned. No tap set needed: nothing in the design is tapped.

Sheet Unmodeled
A1: Item | B1: In the model now? | C1: Needs a model? | D1: What to do
A2: Doser servos x3 (MG996R) | B2: ADDED: CrowBox_FieldModules | C2: done | D2: Placed on the cradles' existing 49.5 x 10 hole pattern, shaft toward the bottle, body hanging outboard.
A3: Signal pod (3 LEDs + buzzer) | B3: ADDED: FieldModules + _SignalPod_print | C3: done | D3: Sits on the bottom plate right of the PIR housing; nose through the PIR slot so the crow sees the LEDs ~45 mm under the reward window. Install before the tray (screw is under it).
A4: Solar charge controller + 8 Ah battery + fuse 1 | B4: ADDED: FieldModules | C4: done | D4: Controller lies flat on the shelf right of the battery; fuse holder on the battery lid.
A5: All cable runs + vision-box glands | B5: ADDED: CrowBox_Wiring_v2 | C5: done | D5: 19 runs, each at its real OD, ending at its gland hole. Replaces CrowBox_CableRoutes_BatteryShelf.
A6: JB gland row | B6: UPDATED: CrowBox_JunctionBox_v2 | C6: done | D6: 3 x PG16 multi-hole + 2 x PG9 in one low row; back panel gets one gland window (Panels_v3).
A7: Doser rotors x3 | B7: no (rotor_60mm.step exists from earlier) | C7: YES | D7: Add on the servo horns and check the pocket sits under the bottle mouth; the earlier rotor predates the MG996R switch.
A8: Gatorade bottles x3 | B8: no (placeholder STEP exists) | C8: YES | D8: Drop into the cradle rings to check bay height and roof clearance.
A9: Corner brackets under the roof top bars x8 | B9: no | C9: YES | D9: Simple; counted in the bracket kit.
A10: Real gate clevises + actuator rear mounts | B10: stand-ins only | C10: YES | D10: Once you pick the rod-end/clevis parts.
A11: Trapdoor hinge / pivot | B11: no | C11: YES | D11: Needed to check the load-cell cable's service loop and the trapdoor swing.
A12: IR beam holders x3 | B12: no (paused) | C12: later | D12: Cable W04 and gland hole G1-UL are reserved.
... A17: Main power switch | B17: no | C17: no | D17: Hole in the JB side wall.
A18: Ground anchors | B18: no | C18: no

Sheet Doc check
A1: Doc item | B1: Qty | C1: In model? | D1: Where / decision | E1: Change vs the doc
A2: ESP32 DevKit V1 + screw-terminal breakout | B2: 1 | C2: inside JB | D2: JB (not modeled by choice)
A3: MCP23017 | B3: 1 | C3: inside JB | D3: JB
A4: L298N | B4: 1 | C4: inside JB | D4: JB | E4: Fine at 3.3 V logic; actuators see ~2 V less than 12 V.
A5: MOSFET driver modules | B5: 2 | C5: inside JB | D5: JB | E5: Use logic-level (AOD4184/D4184) instead of IRF520.
A6: Buck converters with voltmeter | B6: 2 | C6: inside JB | D6: #1 logic 5.1 V; #2 servo rail 6 V | E6: #2 must be >= 5 A.
A7: Notecarrier-A + Notecard | B7: 1 | C7: inside JB | D7: Phase 5; mount on a plastic wall away from the L298N
A8: Main junction box ~300 x 250 x 150 | B8: 1 | C8: Ruilogod 200x120x75 | D8: Back of the box, outside the back panel | E8: Too small. Board footprints ~21,000 mm2 (with spacing) vs 22,400 mm2 floor, before gland space and wiring. Get ~250 x 200 x 100.
A9: Glands on the bottom face | B9: - | C9: back face, low row | D9: Glands pass the back panel into the frame | E9: Back face is inside the panels: no rain reaches it, and cables never run outside.
A10: 12 V LiFePO4 8 Ah | B10: 1 | C10: yes (shelf) | D10: Battery shelf at the bottom back | E10: Own spot (doc's open question). Placeholder updated from 6 Ah to 8 Ah.
A11: Inline fuse 5 A | B11: 1 | C11: yes | D11: Fuse 1 (7.5 A) on the battery lid + fuse 2 (5 A) in the JB | E11: Two fuses: one protects the cable, one is reachable.
A12: WAGO 221 | B12: ~5 | C12: inside JB | E12: ~10 x 221-415 needed.
A13: Main power switch | B13: ? | C13: no | D13: JB side wall | E13: Recommended.
A14: Clear-lid IP65 vision box | B14: 1 | C14: yes | D14: Hangs from the two reward crossbars | E14: Ears drilled to 5.5 mm for M5 T-nuts.
A15: ESP32-P4-NANO / OV5647 camera (was Pi Zero 2 WH / Camera 3 / Coral) | B15: 1 each | C15: no - the fit-check blocks are still the Pi + Coral | D15: Vision box | E15: Replace the Pi + Coral blocks with the P4-NANO (50 x 50) and the OV5647 camera (25 x 24). No Coral; the camera uses its own 15-pin cable.
A16: Vision box cable 4 wires (5 V, GND, TX, RX) | B16: 1 | C16: W08 Cat6 | D16: Cat6, 8 conductors | E16: Carries 12 V + PIR + reward HX711 too; mini buck inside makes 5 V.
A17: Vision box: only one PG7 | B17: - | C17: 3 glands | D17: 2 x PG7 front, 1 x PG9 back | E17: PIR and reward load cell now land in the vision box.
A18: MG996R dosers | B18: 3 | C18: ADDED | D18: On the cradles
A19: MG996R trapdoor | B19: 1 | C19: yes | D19: Pit servo mount
A20: Solenoid deadbolt | B20: 1 | C20: yes | D20: Pit | E20: Add flyback diode.
A21: Linear actuators 50 mm | B21: 2 | C21: yes | D21: Front posts | E21: 50 mm stroke = 44 mm reward window.
A22: Load cells 1 kg | B22: 2 | C22: yes | D22: Reward tray + pit trapdoor | E22: Pit cell rides the trapdoor: 10 cm service loop.
A23: HX711 at each load cell | B23: 2 | C23: no (inside boxes) | D23: #1 in the vision box (99 mm leads); #2 in the JB | E23: Pit run is 1.2 m of shielded 4-core instead of a separate wet-zone box.
A24: PIR facing down into the deposit chamber | B24: 1 | C24: yes | D24: Your PIR housing faces forward out the PIR slot | E24: Model kept as you built it.
A25: IR beam pairs | B25: 3 | C25: paused | D25: Reserved: W04 + gland hole | E25: One shared 6-core instead of 3 cables.
A26: Passive buzzer | B26: 1 | C26: ADDED | D26: Inside the signal pod
A27: Signal LEDs 5 mm | B27: 3 | C27: ADDED | D27: Signal pod, visible through the PIR slot | E27: No front-panel change needed.
A28: 5 V COB strip under the reward floor | B28: 1 | C28: 12 V strip on pit light ring | D28: Pit light ring | E28: 12 V version, switched by MOSFET.
A29: Servo cables need PG9+ for the plug | B29: - | C29: no plugs through glands | D29: Round 3-core through multi-hole PG16 | E29: Servo plugs mate with soldered headers outside the JB.
A30: Solar input (Phase 9) | B30: 0-1 | C30: yes | D30: Roof panel + controller on the shelf | E30: Solar no longer enters the JB.
A31: Reward tray load cell (open question) | B31: - | C31: kept | E31: You confirmed: keep it.

Sheet Model fixes
A1: # | B1: Fix in Fusion | C1: Detail
A2: 1 | B2: Swap in the new files | C2: Delete CrowBox_CableRoutes_BatteryShelf, CrowBox_JunctionBox, CrowBox_Panels_v2. Insert CrowBox_Wiring_v2, CrowBox_FieldModules, CrowBox_JunctionBox_v2, CrowBox_Panels_v3 (all in assembly coordinates).
A3: 2 | B3: Delete 17 duplicate corner brackets | C3: 87 bracket instances sit at 70 positions (2-5 copies at some spots, e.g. 5 at the back-right post Z 280).
A4: 3 | B4: Delete duplicate pit bars | C4: 5537T9 ':13' and ':14' copy the pit's top front/back bars; the two 150 mm verticals inside Object_Pit_v2 sit inside the 170 mm corner verticals.
A5: 4 | B5: Delete the catch-bin placeholder | C5: The unnamed block listed as [0:1:1:171] (X -300..75, Z -409..-153).
A6: 5 | B6: Trim the chute's top tab | C6: Pokes 4.4 mm into the back panel (Y 289.3 vs 284.9).
A7: 6 | B7: Lower the PIR housing + AM312 0.8 mm | C7: Still floats 0.8 mm above the plate.
A8: 7 | B8: Bottom plate thickness | C8: Model 4 mm; order 0.187in (4.75 mm). Extrude the extra 0.75 mm downward; drop the 1 mm shims.
A9: 8 | B9: Gate thickness | C9: Model 4 mm; SCS polycarbonate is 4.5 mm (0.177in).
A10: 9 | B10: Add 8 corner brackets under the roof top bars
A11: 10 | B11: Junction box size | C11: Upsize to ~250 x 200 x 100 and keep the gland row at the same height, or accept a cramped 2-layer build.
A12: 11 | B12: Screw lengths changed | C12: Chute bracket M5x10 (not 12), light ring M5x8 (not 10), perch M5x25 flanged (not 30): the longer ones hit the extrusion core.
A13: 12 | B13: Perch rod | C13: 1-1/4in (31.75 mm) dowel, not a 1-5/16in closet pole.
A14: 13 | B14: Generic 2028 brackets | C14: 2 mm bigger than the modeled McMaster ones: check the bay-floor corner notches (1 mm clearance).
A15: 14 | B15: Reward window height | C15: 50 mm stroke -> 44 mm tall window. 100 mm stroke actuators would open it fully.
A16: 15 | B16: Anchor the box | C16: ~1.9 m tall on 2x2 legs.
A17: 16 | B17: Tiny panel overlaps (ignore) | C17: Left and back panels overlap the posts by 0.026 mm (frame posts are offset 0.074 mm). Not real.
